<rss xmlns:atom="http://www.w3.org/2005/Atom" version="2.0">
    <channel>
        <title>Foreign Key constraint failed - Tag - </title>
        <link>https://colinder.github.io/tags/foreign-key-constraint-failed/</link>
        <description>Foreign Key constraint failed - Tag - </description>
        <generator>Hugo -- gohugo.io</generator><language>en</language><lastBuildDate>Sat, 09 Oct 2021 14:49:10 &#43;0900</lastBuildDate><atom:link href="https://colinder.github.io/tags/foreign-key-constraint-failed/" rel="self" type="application/rss+xml" /><item>
    <title>Django_11_CustomUserhotfix</title>
    <link>https://colinder.github.io/django_11_customuserhotfix/</link>
    <pubDate>Sat, 09 Oct 2021 14:49:10 &#43;0900</pubDate>
    <author>Author</author>
    <guid>https://colinder.github.io/django_11_customuserhotfix/</guid>
    <description><![CDATA[​
Django Foreign Key constraint failed [ 주의! 본 포스팅은 내용이 정확하지 않을 수 있습니다. 수정할 부분은 피드백해주시면 감사드리겠습니다.]
문제는 Custom User Model 을 생성하면서 생긴 user_user 테이블과 기존에 python manage.py createsuperuser 명령어로 어드민 계정이 저장된 auth_user 테이블의 상속문제? 때문에 에러가 발생.
Custom User Model 을 사용할 때 settings.py 에 AUTH_USER_MODEL = '내가만든app이름.User모델' 을 추가하게 되는데 기존의 auth_user 테이블 대신 새로운 user_user 모델을 사용하겠다는 뜻.
그런데 나는 기존에 크롤러 데이터를 확인하기위해 auth_user 에 이미 admin 계정이 하나 생성되어있었던 상황.]]></description>
</item></channel>
</rss>
